Workbook
Name Mes: Parametros!$G$2:$G$13
Name Proveedores: Parametros!$A$2:$A$622
Name Tipo: Parametros!$E$2:$E$6

Sheet Parametros
A1: PROVEEDOR | B1: MOD ENTREGA | C1: Modelo | E1: Tipo Pfolio. | G1: Mes
A2: A51 CLOTHING SAS | B2: CEDI | C2: FIRME | E2: Reprogramable | G2: ENERO
A3: ADRIANA ASTRID PINEDA ALZATE | B3: CEDI | C3: FIRME | E3: Repro Prov. Solo. | G3: FEBRERO
A4: AGREDO NARVAEZ LINDA JENIFFER | B4: CEDI | C4: FIRME | E4: Líneas | G4: MARZO
A5: ALBERTO PAVA OSPINA | B5: CEDI | C5: FIRME | E5: Línea Prov. Solo. | G5: ABRIL
A6: ALEXANDRA GIRALDO CHICA | B6: CEDI | C6: FIRME | E6: Pdp | G6: MAYO
A7: ALIA SIOUFI SEJNAUI | B7: CEDI | C7: VMI | G7: JUNIO
A8: ALIANZA INTEGRAL DE SERVICIO ALISER SAS | B8: CEDI | C8: FIRME | G8: JULIO
A9: ALIANZA TEXTIL MEDELLIN SAS | B9: CEDI | C9: FIRME | G9: AGOSTO
A10: ALISARDO RESTREPO BUITRAGO | B10: CEDI | C10: FIRME | G10: SEPTIEMBRE
A11: ALPHA INTERNATIONAL SAS | B11: CEDI | C11: FIRME | G11: OCTUBRE
A12: ALVARO CARVAJAL SERRANO | B12: CEDI | C12: FIRME | G12: NOVIEMBRE
A13: ALVARO ZAMORA LOMBANA | B13: CEDI | C13: FIRME | G13: DICIEMBRE
A14: ALZATE GIRALDO GABRIELA ORFANY | B14: CEDI | C14: FIRME
A15: AMARTEX SAS | B15: CEDI | C15: FIRME
A16: AMATEX SAS | B16: CEDI | C16: FIRME
A17: AMAYA ROBLES PEDRO JULIO | B17: CEDI | C17: FIRME
A18: AMERICA ZONA LIBRE S.A | B18: CEDI | C18: FIRME
A19: ANDRADE VARGAS LORENA | B19: CEDI | C19: FIRME
A20: ANDRES MAURICIO SANCHEZ MOREANO | B20: CEDI | C20: FIRME
A21: ANGEL ANTONIO REYES QUINTERO | B21: CEDI | C21: FIRME
A22: ANKARA FASHION LTDA (EN CONSIGNACION) | B22: CEDI | C22: VMI
A23: ANKARA FHASHION LTDA | B23: CEDI | C23: FIRME
A24: APEX GROUP SAS | B24: CEDI | C24: FIRME
A25: ARCITEX SAS | B25: CEDI | C25: FIRME
... A629: SHERON SAS | B629: CEDI | C629: VMI

Sheet Consolidado
I1: Total GNR -> | J1: =SUBTOTAL(9,J3:J1048576) -> 577381.62
A2: Codigo | B2: Categoría | C2: Consumidor | D2: Universo | E2: Producto | F2: Tendencia | G2: RN | H2: Talla | I2: Color | J2: Cantidad | K2: Mes | L2: Fecha llegada | M2: Desc. Prov. | N2: Tipo | O2: Precio | P2: Modelo | Q2: Cross Docking | R2: Observación | S2: Observaciones comprador | T2: cat | U2: c | V2: Observación1
A3: REF LN FM BTA 45 | B3: BEBITA | C3: EXPLORADOR | D3: DEPORTIVO | E3: CAMISETA | F3: MODA | G3: 1 | H3: 18-24 | I3: 1 | J3: 0 | K3: FEBRERO | L3: 45341 | M3: - | N3: FIRME | O3: 0 | P3: Líneas | Q3: CEDI | R3: BEBITAEXPLORADORDEPORTIVOCAMISETAMODA | S3: NO ES CURVA MINIMA | T3: =+IF(B3="NINA","INFANTIL",IF(B3="NINO","INFANTIL",IF(B3="BEBITA","INFANTIL",IF(B3="BEBITO","INFANTIL",IF(B3="BEBE","INFANTIL",IF(B3="HOGAR","HOGAR Y COMPLEMENTOS",IF(B3="COMPLEMENTOS","HOGAR Y COMPLEMENTOS",IF(B3="COLEGIAL","HOGAR Y COMPLEMENTOS",IF(B3="INT MUJER","INTERIOR",IF(B3="INT HOMBRE","INTERIOR",IF(B3="INT NINA","INTERIOR",IF(B3="INT NINO","INTERIOR",IF(B3="INT BEBITA","INTERIOR",IF(B3="INT BEBITO","INTERIOR",IF(B3="MUJER","MUJER",IF(B3="HOMBRE","HOMBRE","")))))))))))))))) -> INFANTIL | V3: Planeación Inicial | AA3: =+CONCATENATE(T3,B3,C3,D3,E3,F3) -> INFANTILBEBITAEXPLORADORDEPORTIVOCAMISETAMODA
A4: REF LN FM BTA 45 | B4: BEBITA | C4: EXPLORADOR | D4: DEPORTIVO | E4: CAMISETA | F4: MODA | G4: 1 | H4: 12-18 | I4: 1 | J4: 0 | K4: FEBRERO | L4: 45341 | M4: - | N4: FIRME | O4: 0 | P4: Líneas | Q4: CEDI | R4: BEBITAEXPLORADORDEPORTIVOCAMISETAMODA | S4: NO ES CURVA MINIMA | T4: =+IF(B4="NINA","INFANTIL",IF(B4="NINO","INFANTIL",IF(B4="BEBITA","INFANTIL",IF(B4="BEBITO","INFANTIL",IF(B4="BEBE","INFANTIL",IF(B4="HOGAR","HOGAR Y COMPLEMENTOS",IF(B4="COMPLEMENTOS","HOGAR Y COMPLEMENTOS",IF(B4="COLEGIAL","HOGAR Y COMPLEMENTOS",IF(B4="INT MUJER","INTERIOR",IF(B4="INT HOMBRE","INTERIOR",IF(B4="INT NINA","INTERIOR",IF(B4="INT NINO","INTERIOR",IF(B4="INT BEBITA","INTERIOR",IF(B4="INT BEBITO","INTERIOR",IF(B4="MUJER","MUJER",IF(B4="HOMBRE","HOMBRE","")))))))))))))))) -> INFANTIL | V4: Planeación Inicial | AA4: =+CONCATENATE(T4,B4,C4,D4,E4,F4) -> INFANTILBEBITAEXPLORADORDEPORTIVOCAMISETAMODA
A5: REF LN FM BTA 45 | B5: BEBITA | C5: EXPLORADOR | D5: DEPORTIVO | E5: CAMISETA | F5: MODA | G5: 1 | H5: 6-12 | I5: 1 | J5: 0 | K5: FEBRERO | L5: 45341 | M5: - | N5: FIRME | O5: 0 | P5: Líneas | Q5: CEDI | R5: BEBITAEXPLORADORDEPORTIVOCAMISETAMODA | S5: NO ES CURVA MINIMA | T5: =+IF(B5="NINA","INFANTIL",IF(B5="NINO","INFANTIL",IF(B5="BEBITA","INFANTIL",IF(B5="BEBITO","INFANTIL",IF(B5="BEBE","INFANTIL",IF(B5="HOGAR","HOGAR Y COMPLEMENTOS",IF(B5="COMPLEMENTOS","HOGAR Y COMPLEMENTOS",IF(B5="COLEGIAL","HOGAR Y COMPLEMENTOS",IF(B5="INT MUJER","INTERIOR",IF(B5="INT HOMBRE","INTERIOR",IF(B5="INT NINA","INTERIOR",IF(B5="INT NINO","INTERIOR",IF(B5="INT BEBITA","INTERIOR",IF(B5="INT BEBITO","INTERIOR",IF(B5="MUJER","MUJER",IF(B5="HOMBRE","HOMBRE","")))))))))))))))) -> INFANTIL | V5: Planeación Inicial | AA5: =+CONCATENATE(T5,B5,C5,D5,E5,F5) -> INFANTILBEBITAEXPLORADORDEPORTIVOCAMISETAMODA
A6: REF LN FM BTA 45 | B6: BEBITA | C6: EXPLORADOR | D6: DEPORTIVO | E6: CAMISETA | F6: MODA | G6: 1 | H6: 24-36 | I6: 1 | J6: 0 | K6: FEBRERO | L6: 45341 | M6: - | N6: FIRME | O6: 0 | P6: Líneas | Q6: CEDI | R6: BEBITAEXPLORADORDEPORTIVOCAMISETAMODA | S6: NO ES CURVA MINIMA | T6: =+IF(B6="NINA","INFANTIL",IF(B6="NINO","INFANTIL",IF(B6="BEBITA","INFANTIL",IF(B6="BEBITO","INFANTIL",IF(B6="BEBE","INFANTIL",IF(B6="HOGAR","HOGAR Y COMPLEMENTOS",IF(B6="COMPLEMENTOS","HOGAR Y COMPLEMENTOS",IF(B6="COLEGIAL","HOGAR Y COMPLEMENTOS",IF(B6="INT MUJER","INTERIOR",IF(B6="INT HOMBRE","INTERIOR",IF(B6="INT NINA","INTERIOR",IF(B6="INT NINO","INTERIOR",IF(B6="INT BEBITA","INTERIOR",IF(B6="INT BEBITO","INTERIOR",IF(B6="MUJER","MUJER",IF(B6="HOMBRE","HOMBRE","")))))))))))))))) -> INFANTIL | V6: Planeación Inicial | AA6: =+CONCATENATE(T6,B6,C6,D6,E6,F6) -> INFANTILBEBITAEXPLORADORDEPORTIVOCAMISETAMODA
A7: REF LN FM BTA 52 | B7: BEBITA | C7: EXPLORADOR | D7: DESCANSO | E7: CONJUNTO | F7: BASICO MODA | G7: 1 | H7: 18-24 | I7: 1 | J7: 0 | K7: FEBRERO | L7: 45331 | M7: - | N7: FIRME | O7: 0 | P7: Líneas | Q7: CEDI | R7: BEBITAEXPLORADORDESCANSOCONJUNTOBASICO MODA | T7: =+IF(B7="NINA","INFANTIL",IF(B7="NINO","INFANTIL",IF(B7="BEBITA","INFANTIL",IF(B7="BEBITO","INFANTIL",IF(B7="BEBE","INFANTIL",IF(B7="HOGAR","HOGAR Y COMPLEMENTOS",IF(B7="COMPLEMENTOS","HOGAR Y COMPLEMENTOS",IF(B7="COLEGIAL","HOGAR Y COMPLEMENTOS",IF(B7="INT MUJER","INTERIOR",IF(B7="INT HOMBRE","INTERIOR",IF(B7="INT NINA","INTERIOR",IF(B7="INT NINO","INTERIOR",IF(B7="INT BEBITA","INTERIOR",IF(B7="INT BEBITO","INTERIOR",IF(B7="MUJER","MUJER",IF(B7="HOMBRE","HOMBRE","")))))))))))))))) -> INFANTIL | V7: Planeación Inicial | AA7: =+CONCATENATE(T7,B7,C7,D7,E7,F7) -> INFANTILBEBITAEXPLORADORDESCANSOCONJUNTOBASICO MODA
A8: REF LN FM BTA 52 | B8: BEBITA | C8: EXPLORADOR | D8: DESCANSO | E8: CONJUNTO | F8: BASICO MODA | G8: 1 | H8: 12-18 | I8: 1 | J8: 0 | K8: FEBRERO | L8: 45331 | M8: - | N8: FIRME | O8: 0 | P8: Líneas | Q8: CEDI | R8: BEBITAEXPLORADORDESCANSOCONJUNTOBASICO MODA | T8: =+IF(B8="NINA","INFANTIL",IF(B8="NINO","INFANTIL",IF(B8="BEBITA","INFANTIL",IF(B8="BEBITO","INFANTIL",IF(B8="BEBE","INFANTIL",IF(B8="HOGAR","HOGAR Y COMPLEMENTOS",IF(B8="COMPLEMENTOS","HOGAR Y COMPLEMENTOS",IF(B8="COLEGIAL","HOGAR Y COMPLEMENTOS",IF(B8="INT MUJER","INTERIOR",IF(B8="INT HOMBRE","INTERIOR",IF(B8="INT NINA","INTERIOR",IF(B8="INT NINO","INTERIOR",IF(B8="INT BEBITA","INTERIOR",IF(B8="INT BEBITO","INTERIOR",IF(B8="MUJER","MUJER",IF(B8="HOMBRE","HOMBRE","")))))))))))))))) -> INFANTIL | V8: Planeación Inicial | AA8: =+CONCATENATE(T8,B8,C8,D8,E8,F8) -> INFANTILBEBITAEXPLORADORDESCANSOCONJUNTOBASICO MODA
A9: REF LN FM BTA 52 | B9: BEBITA | C9: EXPLORADOR | D9: DESCANSO | E9: CONJUNTO | F9: BASICO MODA | G9: 1 | H9: 6-12 | I9: 1 | J9: 0 | K9: FEBRERO | L9: 45331 | M9: - | N9: FIRME | O9: 0 | P9: Líneas | Q9: CEDI | R9: BEBITAEXPLORADORDESCANSOCONJUNTOBASICO MODA | T9: =+IF(B9="NINA","INFANTIL",IF(B9="NINO","INFANTIL",IF(B9="BEBITA","INFANTIL",IF(B9="BEBITO","INFANTIL",IF(B9="BEBE","INFANTIL",IF(B9="HOGAR","HOGAR Y COMPLEMENTOS",IF(B9="COMPLEMENTOS","HOGAR Y COMPLEMENTOS",IF(B9="COLEGIAL","HOGAR Y COMPLEMENTOS",IF(B9="INT MUJER","INTERIOR",IF(B9="INT HOMBRE","INTERIOR",IF(B9="INT NINA","INTERIOR",IF(B9="INT NINO","INTERIOR",IF(B9="INT BEBITA","INTERIOR",IF(B9="INT BEBITO","INTERIOR",IF(B9="MUJER","MUJER",IF(B9="HOMBRE","HOMBRE","")))))))))))))))) -> INFANTIL | V9: Planeación Inicial | AA9: =+CONCATENATE(T9,B9,C9,D9,E9,F9) -> INFANTILBEBITAEXPLORADORDESCANSOCONJUNTOBASICO MODA
A10: REF LN FM BTA 52 | B10: BEBITA | C10: EXPLORADOR | D10: DESCANSO | E10: CONJUNTO | F10: BASICO MODA | G10: 1 | H10: 24-36 | I10: 1 | J10: 0 | K10: FEBRERO | L10: 45331 | M10: - | N10: FIRME | O10: 0 | P10: Líneas | Q10: CEDI | R10: BEBITAEXPLORADORDESCANSOCONJUNTOBASICO MODA | T10: =+IF(B10="NINA","INFANTIL",IF(B10="NINO","INFANTIL",IF(B10="BEBITA","INFANTIL",IF(B10="BEBITO","INFANTIL",IF(B10="BEBE","INFANTIL",IF(B10="HOGAR","HOGAR Y COMPLEMENTOS",IF(B10="COMPLEMENTOS","HOGAR Y COMPLEMENTOS",IF(B10="COLEGIAL","HOGAR Y COMPLEMENTOS",IF(B10="INT MUJER","INTERIOR",IF(B10="INT HOMBRE","INTERIOR",IF(B10="INT NINA","INTERIOR",IF(B10="INT NINO","INTERIOR",IF(B10="INT BEBITA","INTERIOR",IF(B10="INT BEBITO","INTERIOR",IF(B10="MUJER","MUJER",IF(B10="HOMBRE","HOMBRE","")))))))))))))))) -> INFANTIL | V10: Planeación Inicial | AA10: =+CONCATENATE(T10,B10,C10,D10,E10,F10) -> INFANTILBEBITAEXPLORADORDESCANSOCONJUNTOBASICO MODA
A11: REF LN FM BTA 53 | B11: BEBITA | C11: EXPLORADOR | D11: DESCANSO | E11: CONJUNTO | F11: MODA | G11: 1 | H11: 18-24 | I11: 1 | J11: 0 | K11: FEBRERO | L11: 45334 | M11: - | N11: FIRME | O11: 0 | P11: Líneas | Q11: CEDI | R11: BEBITAEXPLORADORDESCANSOCONJUNTOMODA | T11: =+IF(B11="NINA","INFANTIL",IF(B11="NINO","INFANTIL",IF(B11="BEBITA","INFANTIL",IF(B11="BEBITO","INFANTIL",IF(B11="BEBE","INFANTIL",IF(B11="HOGAR","HOGAR Y COMPLEMENTOS",IF(B11="COMPLEMENTOS","HOGAR Y COMPLEMENTOS",IF(B11="COLEGIAL","HOGAR Y COMPLEMENTOS",IF(B11="INT MUJER","INTERIOR",IF(B11="INT HOMBRE","INTERIOR",IF(B11="INT NINA","INTERIOR",IF(B11="INT NINO","INTERIOR",IF(B11="INT BEBITA","INTERIOR",IF(B11="INT BEBITO","INTERIOR",IF(B11="MUJER","MUJER",IF(B11="HOMBRE","HOMBRE","")))))))))))))))) -> INFANTIL | V11: Planeación Inicial | AA11: =+CONCATENATE(T11,B11,C11,D11,E11,F11) -> INFANTILBEBITAEXPLORADORDESCANSOCONJUNTOMODA
A12: REF LN FM BTA 53 | B12: BEBITA | C12: EXPLORADOR | D12: DESCANSO | E12: CONJUNTO | F12: MODA | G12: 1 | H12: 12-18 | I12: 1 | J12: 0 | K12: FEBRERO | L12: 45334 | M12: - | N12: FIRME | O12: 0 | P12: Líneas | Q12: CEDI | R12: BEBITAEXPLORADORDESCANSOCONJUNTOMODA | T12: =+IF(B12="NINA","INFANTIL",IF(B12="NINO","INFANTIL",IF(B12="BEBITA","INFANTIL",IF(B12="BEBITO","INFANTIL",IF(B12="BEBE","INFANTIL",IF(B12="HOGAR","HOGAR Y COMPLEMENTOS",IF(B12="COMPLEMENTOS","HOGAR Y COMPLEMENTOS",IF(B12="COLEGIAL","HOGAR Y COMPLEMENTOS",IF(B12="INT MUJER","INTERIOR",IF(B12="INT HOMBRE","INTERIOR",IF(B12="INT NINA","INTERIOR",IF(B12="INT NINO","INTERIOR",IF(B12="INT BEBITA","INTERIOR",IF(B12="INT BEBITO","INTERIOR",IF(B12="MUJER","MUJER",IF(B12="HOMBRE","HOMBRE","")))))))))))))))) -> INFANTIL | V12: Planeación Inicial | AA12: =+CONCATENATE(T12,B12,C12,D12,E12,F12) -> INFANTILBEBITAEXPLORADORDESCANSOCONJUNTOMODA
A13: REF LN FM BTA 53 | B13: BEBITA | C13: EXPLORADOR | D13: DESCANSO | E13: CONJUNTO | F13: MODA | G13: 1 | H13: 6-12 | I13: 1 | J13: 0 | K13: FEBRERO | L13: 45334 | M13: - | N13: FIRME | O13: 0 | P13: Líneas | Q13: CEDI | R13: BEBITAEXPLORADORDESCANSOCONJUNTOMODA | T13: =+IF(B13="NINA","INFANTIL",IF(B13="NINO","INFANTIL",IF(B13="BEBITA","INFANTIL",IF(B13="BEBITO","INFANTIL",IF(B13="BEBE","INFANTIL",IF(B13="HOGAR","HOGAR Y COMPLEMENTOS",IF(B13="COMPLEMENTOS","HOGAR Y COMPLEMENTOS",IF(B13="COLEGIAL","HOGAR Y COMPLEMENTOS",IF(B13="INT MUJER","INTERIOR",IF(B13="INT HOMBRE","INTERIOR",IF(B13="INT NINA","INTERIOR",IF(B13="INT NINO","INTERIOR",IF(B13="INT BEBITA","INTERIOR",IF(B13="INT BEBITO","INTERIOR",IF(B13="MUJER","MUJER",IF(B13="HOMBRE","HOMBRE","")))))))))))))))) -> INFANTIL | V13: Planeación Inicial | AA13: =+CONCATENATE(T13,B13,C13,D13,E13,F13) -> INFANTILBEBITAEXPLORADORDESCANSOCONJUNTOMODA
A14: REF LN FM BTA 53 | B14: BEBITA | C14: EXPLORADOR | D14: DESCANSO | E14: CONJUNTO | F14: MODA | G14: 1 | H14: 24-36 | I14: 1 | J14: 0 | K14: FEBRERO | L14: 45334 | M14: - | N14: FIRME | O14: 0 | P14: Líneas | Q14: CEDI | R14: BEBITAEXPLORADORDESCANSOCONJUNTOMODA | T14: =+IF(B14="NINA","INFANTIL",IF(B14="NINO","INFANTIL",IF(B14="BEBITA","INFANTIL",IF(B14="BEBITO","INFANTIL",IF(B14="BEBE","INFANTIL",IF(B14="HOGAR","HOGAR Y COMPLEMENTOS",IF(B14="COMPLEMENTOS","HOGAR Y COMPLEMENTOS",IF(B14="COLEGIAL","HOGAR Y COMPLEMENTOS",IF(B14="INT MUJER","INTERIOR",IF(B14="INT HOMBRE","INTERIOR",IF(B14="INT NINA","INTERIOR",IF(B14="INT NINO","INTERIOR",IF(B14="INT BEBITA","INTERIOR",IF(B14="INT BEBITO","INTERIOR",IF(B14="MUJER","MUJER",IF(B14="HOMBRE","HOMBRE","")))))))))))))))) -> INFANTIL | V14: Planeación Inicial | AA14: =+CONCATENATE(T14,B14,C14,D14,E14,F14) -> INFANTILBEBITAEXPLORADORDESCANSOCONJUNTOMODA
A15: REF LN FM BTA 54 | B15: BEBITA | C15: EXPLORADOR | D15: DESCANSO | E15: CONJUNTO | F15: MODA | G15: 1 | H15: 18-24 | I15: 1 | J15: 0 | K15: FEBRERO | L15: 45334 | M15: - | N15: FIRME | O15: 0 | P15: Líneas | Q15: CEDI | R15: BEBITAEXPLORADORDESCANSOCONJUNTOMODA | T15: =+IF(B15="NINA","INFANTIL",IF(B15="NINO","INFANTIL",IF(B15="BEBITA","INFANTIL",IF(B15="BEBITO","INFANTIL",IF(B15="BEBE","INFANTIL",IF(B15="HOGAR","HOGAR Y COMPLEMENTOS",IF(B15="COMPLEMENTOS","HOGAR Y COMPLEMENTOS",IF(B15="COLEGIAL","HOGAR Y COMPLEMENTOS",IF(B15="INT MUJER","INTERIOR",IF(B15="INT HOMBRE","INTERIOR",IF(B15="INT NINA","INTERIOR",IF(B15="INT NINO","INTERIOR",IF(B15="INT BEBITA","INTERIOR",IF(B15="INT BEBITO","INTERIOR",IF(B15="MUJER","MUJER",IF(B15="HOMBRE","HOMBRE","")))))))))))))))) -> INFANTIL | V15: Planeación Inicial | AA15: =+CONCATENATE(T15,B15,C15,D15,E15,F15) -> INFANTILBEBITAEXPLORADORDESCANSOCONJUNTOMODA
A16: REF LN FM BTA 54 | B16: BEBITA | C16: EXPLORADOR | D16: DESCANSO | E16: CONJUNTO | F16: MODA | G16: 1 | H16: 12-18 | I16: 1 | J16: 0 | K16: FEBRERO | L16: 45334 | M16: - | N16: FIRME | O16: 0 | P16: Líneas | Q16: CEDI | R16: BEBITAEXPLORADORDESCANSOCONJUNTOMODA | T16: =+IF(B16="NINA","INFANTIL",IF(B16="NINO","INFANTIL",IF(B16="BEBITA","INFANTIL",IF(B16="BEBITO","INFANTIL",IF(B16="BEBE","INFANTIL",IF(B16="HOGAR","HOGAR Y COMPLEMENTOS",IF(B16="COMPLEMENTOS","HOGAR Y COMPLEMENTOS",IF(B16="COLEGIAL","HOGAR Y COMPLEMENTOS",IF(B16="INT MUJER","INTERIOR",IF(B16="INT HOMBRE","INTERIOR",IF(B16="INT NINA","INTERIOR",IF(B16="INT NINO","INTERIOR",IF(B16="INT BEBITA","INTERIOR",IF(B16="INT BEBITO","INTERIOR",IF(B16="MUJER","MUJER",IF(B16="HOMBRE","HOMBRE","")))))))))))))))) -> INFANTIL | V16: Planeación Inicial | AA16: =+CONCATENATE(T16,B16,C16,D16,E16,F16) -> INFANTILBEBITAEXPLORADORDESCANSOCONJUNTOMODA
A17: REF LN FM BTA 54 | B17: BEBITA | C17: EXPLORADOR | D17: DESCANSO | E17: CONJUNTO | F17: MODA | G17: 1 | H17: 6-12 | I17: 1 | J17: 0 | K17: FEBRERO | L17: 45334 | M17: - | N17: FIRME | O17: 0 | P17: Líneas | Q17: CEDI | R17: BEBITAEXPLORADORDESCANSOCONJUNTOMODA | T17: =+IF(B17="NINA","INFANTIL",IF(B17="NINO","INFANTIL",IF(B17="BEBITA","INFANTIL",IF(B17="BEBITO","INFANTIL",IF(B17="BEBE","INFANTIL",IF(B17="HOGAR","HOGAR Y COMPLEMENTOS",IF(B17="COMPLEMENTOS","HOGAR Y COMPLEMENTOS",IF(B17="COLEGIAL","HOGAR Y COMPLEMENTOS",IF(B17="INT MUJER","INTERIOR",IF(B17="INT HOMBRE","INTERIOR",IF(B17="INT NINA","INTERIOR",IF(B17="INT NINO","INTERIOR",IF(B17="INT BEBITA","INTERIOR",IF(B17="INT BEBITO","INTERIOR",IF(B17="MUJER","MUJER",IF(B17="HOMBRE","HOMBRE","")))))))))))))))) -> INFANTIL | V17: Planeación Inicial | AA17: =+CONCATENATE(T17,B17,C17,D17,E17,F17) -> INFANTILBEBITAEXPLORADORDESCANSOCONJUNTOMODA
A18: REF LN FM BTA 54 | B18: BEBITA | C18: EXPLORADOR | D18: DESCANSO | E18: CONJUNTO | F18: MODA | G18: 1 | H18: 24-36 | I18: 1 | J18: 0 | K18: FEBRERO | L18: 45334 | M18: - | N18: FIRME | O18: 0 | P18: Líneas | Q18: CEDI | R18: BEBITAEXPLORADORDESCANSOCONJUNTOMODA | T18: =+IF(B18="NINA","INFANTIL",IF(B18="NINO","INFANTIL",IF(B18="BEBITA","INFANTIL",IF(B18="BEBITO","INFANTIL",IF(B18="BEBE","INFANTIL",IF(B18="HOGAR","HOGAR Y COMPLEMENTOS",IF(B18="COMPLEMENTOS","HOGAR Y COMPLEMENTOS",IF(B18="COLEGIAL","HOGAR Y COMPLEMENTOS",IF(B18="INT MUJER","INTERIOR",IF(B18="INT HOMBRE","INTERIOR",IF(B18="INT NINA","INTERIOR",IF(B18="INT NINO","INTERIOR",IF(B18="INT BEBITA","INTERIOR",IF(B18="INT BEBITO","INTERIOR",IF(B18="MUJER","MUJER",IF(B18="HOMBRE","HOMBRE","")))))))))))))))) -> INFANTIL | V18: Planeación Inicial | AA18: =+CONCATENATE(T18,B18,C18,D18,E18,F18) -> INFANTILBEBITAEXPLORADORDESCANSOCONJUNTOMODA
... A22: REF LN FM BTA 55 | B22: BEBITA | C22: EXPLORADOR | D22: DESCANSO | E22: CONJUNTO | F22: MODA | G22: 1 | H22: 24-36 | I22: 1 | J22: 0 | K22: FEBRERO | L22: 45334 | M22: - | N22: FIRME | O22: 0 | P22: Líneas | Q22: CEDI | R22: BEBITAEXPLORADORDESCANSOCONJUNTOMODA | T22: =+IF(B22="NINA","INFANTIL",IF(B22="NINO","INFANTIL",IF(B22="BEBITA","INFANTIL",IF(B22="BEBITO","INFANTIL",IF(B22="BEBE","INFANTIL",IF(B22="HOGAR","HOGAR Y COMPLEMENTOS",IF(B22="COMPLEMENTOS","HOGAR Y COMPLEMENTOS",IF(B22="COLEGIAL","HOGAR Y COMPLEMENTOS",IF(B22="INT MUJER","INTERIOR",IF(B22="INT HOMBRE","INTERIOR",IF(B22="INT NINA","INTERIOR",IF(B22="INT NINO","INTERIOR",IF(B22="INT BEBITA","INTERIOR",IF(B22="INT BEBITO","INTERIOR",IF(B22="MUJER","MUJER",IF(B22="HOMBRE","HOMBRE","")))))))))))))))) -> INFANTIL | V22: Planeación Inicial | AA22: =+CONCATENATE(T22,B22,C22,D22,E22,F22) -> INFANTILBEBITAEXPLORADORDESCANSOCONJUNTOMODA
A23: 269539 | B23: BEBITA | C23: DORMILON | D23: DESCANSO | E23: ESTUCHES | F23: BASICO MODA | G23: 1 | H23: NA | I23: NA | J23: 400 | K23: FEBRERO | L23: 45337 | M23: ALZATE GIRALDO ANGELA MARIBEL Y/O ALZATE GRIRALDO GABRIELA ORFANY | N23: FIRME | O23: 0 | P23: Reprogramable | Q23: CEDI | R23: BEBITADORMILONDESCANSOESTUCHESBASICO MODA | T23: =+IF(B23="NINA","INFANTIL",IF(B23="NINO","INFANTIL",IF(B23="BEBITA","INFANTIL",IF(B23="BEBITO","INFANTIL",IF(B23="BEBE","INFANTIL",IF(B23="HOGAR","HOGAR Y COMPLEMENTOS",IF(B23="COMPLEMENTOS","HOGAR Y COMPLEMENTOS",IF(B23="COLEGIAL","HOGAR Y COMPLEMENTOS",IF(B23="INT MUJER","INTERIOR",IF(B23="INT HOMBRE","INTERIOR",IF(B23="INT NINA","INTERIOR",IF(B23="INT NINO","INTERIOR",IF(B23="INT BEBITA","INTERIOR",IF(B23="INT BEBITO","INTERIOR",IF(B23="MUJER","MUJER",IF(B23="HOMBRE","HOMBRE","")))))))))))))))) -> INFANTIL | V23: Planeación Inicial | AA23: =+CONCATENATE(T23,B23,C23,D23,E23,F23) -> INFANTILBEBITADORMILONDESCANSOESTUCHESBASICO MODA
A24: 309253 | B24: BEBITA | C24: DORMILON | D24: DEPORTIVO | E24: CALZADO | F24: MODA | G24: 1 | H24: NA | I24: NA | J24: 173 | K24: FEBRERO | L24: 45337 | M24: ALZATE GIRALDO ANGELA MARIBEL Y/O ALZATE GRIRALDO GABRIELA ORFANY | N24: FIRME | O24: 0 | P24: Reprogramable | Q24: CEDI | R24: BEBITADORMILONDEPORTIVOCALZADOMODA | T24: =+IF(B24="NINA","INFANTIL",IF(B24="NINO","INFANTIL",IF(B24="BEBITA","INFANTIL",IF(B24="BEBITO","INFANTIL",IF(B24="BEBE","INFANTIL",IF(B24="HOGAR","HOGAR Y COMPLEMENTOS",IF(B24="COMPLEMENTOS","HOGAR Y COMPLEMENTOS",IF(B24="COLEGIAL","HOGAR Y COMPLEMENTOS",IF(B24="INT MUJER","INTERIOR",IF(B24="INT HOMBRE","INTERIOR",IF(B24="INT NINA","INTERIOR",IF(B24="INT NINO","INTERIOR",IF(B24="INT BEBITA","INTERIOR",IF(B24="INT BEBITO","INTERIOR",IF(B24="MUJER","MUJER",IF(B24="HOMBRE","HOMBRE","")))))))))))))))) -> INFANTIL | V24: Planeación Inicial | AA24: =+CONCATENATE(T24,B24,C24,D24,E24,F24) -> INFANTILBEBITADORMILONDEPORTIVOCALZADOMODA
A25: REF PDP 1T23 | B25: BEBITA | C25: EXPLORADOR | D25: DEPORTIVO | E25: CONJUNTO | F25: BASICO MODA | G25: 1 | H25: 6-12 | I25: NA | J25: 94 | K25: FEBRERO | L25: 45342 | M25: BOMBOO | N25: VMI | O25: 19900 | P25: PDP | Q25: CEDI | R25: BEBITAEXPLORADORDEPORTIVOCONJUNTOBASICO MODA | T25: =+IF(B25="NINA","INFANTIL",IF(B25="NINO","INFANTIL",IF(B25="BEBITA","INFANTIL",IF(B25="BEBITO","INFANTIL",IF(B25="BEBE","INFANTIL",IF(B25="HOGAR","HOGAR Y COMPLEMENTOS",IF(B25="COMPLEMENTOS","HOGAR Y COMPLEMENTOS",IF(B25="COLEGIAL","HOGAR Y COMPLEMENTOS",IF(B25="INT MUJER","INTERIOR",IF(B25="INT HOMBRE","INTERIOR",IF(B25="INT NINA","INTERIOR",IF(B25="INT NINO","INTERIOR",IF(B25="INT BEBITA","INTERIOR",IF(B25="INT BEBITO","INTERIOR",IF(B25="MUJER","MUJER",IF(B25="HOMBRE","HOMBRE","")))))))))))))))) -> INFANTIL | V25: Planeación Inicial | AA25: =+CONCATENATE(T25,B25,C25,D25,E25,F25) -> INFANTILBEBITAEXPLORADORDEPORTIVOCONJUNTOBASICO MODA
A26: REF PDP 1T23 | B26: BEBITA | C26: EXPLORADOR | D26: DEPORTIVO | E26: CONJUNTO | F26: BASICO MODA | G26: 1 | H26: 12-18 | I26: NA | J26: 86 | K26: FEBRERO | L26: 45342 | M26: BOMBOO | N26: VMI | O26: 19900 | P26: PDP | Q26: CEDI | R26: BEBITAEXPLORADORDEPORTIVOCONJUNTOBASICO MODA | T26: =+IF(B26="NINA","INFANTIL",IF(B26="NINO","INFANTIL",IF(B26="BEBITA","INFANTIL",IF(B26="BEBITO","INFANTIL",IF(B26="BEBE","INFANTIL",IF(B26="HOGAR","HOGAR Y COMPLEMENTOS",IF(B26="COMPLEMENTOS","HOGAR Y COMPLEMENTOS",IF(B26="COLEGIAL","HOGAR Y COMPLEMENTOS",IF(B26="INT MUJER","INTERIOR",IF(B26="INT HOMBRE","INTERIOR",IF(B26="INT NINA","INTERIOR",IF(B26="INT NINO","INTERIOR",IF(B26="INT BEBITA","INTERIOR",IF(B26="INT BEBITO","INTERIOR",IF(B26="MUJER","MUJER",IF(B26="HOMBRE","HOMBRE","")))))))))))))))) -> INFANTIL | V26: Planeación Inicial | AA26: =+CONCATENATE(T26,B26,C26,D26,E26,F26) -> INFANTILBEBITAEXPLORADORDEPORTIVOCONJUNTOBASICO MODA
A27: REF PDP 1T23 | B27: BEBITA | C27: EXPLORADOR | D27: DEPORTIVO | E27: CONJUNTO | F27: BASICO MODA | G27: 1 | H27: 18-24 | I27: NA | J27: 120 | K27: FEBRERO | L27: 45342 | M27: BOMBOO | N27: VMI | O27: 19900 | P27: PDP | Q27: CEDI | R27: BEBITAEXPLORADORDEPORTIVOCONJUNTOBASICO MODA | T27: =+IF(B27="NINA","INFANTIL",IF(B27="NINO","INFANTIL",IF(B27="BEBITA","INFANTIL",IF(B27="BEBITO","INFANTIL",IF(B27="BEBE","INFANTIL",IF(B27="HOGAR","HOGAR Y COMPLEMENTOS",IF(B27="COMPLEMENTOS","HOGAR Y COMPLEMENTOS",IF(B27="COLEGIAL","HOGAR Y COMPLEMENTOS",IF(B27="INT MUJER","INTERIOR",IF(B27="INT HOMBRE","INTERIOR",IF(B27="INT NINA","INTERIOR",IF(B27="INT NINO","INTERIOR",IF(B27="INT BEBITA","INTERIOR",IF(B27="INT BEBITO","INTERIOR",IF(B27="MUJER","MUJER",IF(B27="HOMBRE","HOMBRE","")))))))))))))))) -> INFANTIL | V27: Planeación Inicial | AA27: =+CONCATENATE(T27,B27,C27,D27,E27,F27) -> INFANTILBEBITAEXPLORADORDEPORTIVOCONJUNTOBASICO MODA
A28: REF PDP 1T23 | B28: BEBITA | C28: EXPLORADOR | D28: DEPORTIVO | E28: CONJUNTO | F28: BASICO MODA | G28: 1 | H28: 24-36 | I28: NA | J28: 120 | K28: FEBRERO | L28: 45342 | M28: BOMBOO | N28: VMI | O28: 19900 | P28: PDP | Q28: CEDI | R28: BEBITAEXPLORADORDEPORTIVOCONJUNTOBASICO MODA | T28: =+IF(B28="NINA","INFANTIL",IF(B28="NINO","INFANTIL",IF(B28="BEBITA","INFANTIL",IF(B28="BEBITO","INFANTIL",IF(B28="BEBE","INFANTIL",IF(B28="HOGAR","HOGAR Y COMPLEMENTOS",IF(B28="COMPLEMENTOS","HOGAR Y COMPLEMENTOS",IF(B28="COLEGIAL","HOGAR Y COMPLEMENTOS",IF(B28="INT MUJER","INTERIOR",IF(B28="INT HOMBRE","INTERIOR",IF(B28="INT NINA","INTERIOR",IF(B28="INT NINO","INTERIOR",IF(B28="INT BEBITA","INTERIOR",IF(B28="INT BEBITO","INTERIOR",IF(B28="MUJER","MUJER",IF(B28="HOMBRE","HOMBRE","")))))))))))))))) -> INFANTIL | V28: Planeación Inicial | AA28: =+CONCATENATE(T28,B28,C28,D28,E28,F28) -> INFANTILBEBITAEXPLORADORDEPORTIVOCONJUNTOBASICO MODA
A29: REF LN FM BTA 49 | B29: BEBITA | C29: EXPLORADOR | D29: DEPORTIVO | E29: CONJUNTO | F29: BASICO MODA | G29: 1 | H29: 18-24 | I29: 1 | J29: 112 | K29: FEBRERO | L29: 45337 | M29: C.I CREYTEX S.A.S | N29: FIRME | O29: 0 | P29: Líneas | Q29: CEDI | R29: BEBITAEXPLORADORDEPORTIVOCONJUNTOBASICO MODA | T29: =+IF(B29="NINA","INFANTIL",IF(B29="NINO","INFANTIL",IF(B29="BEBITA","INFANTIL",IF(B29="BEBITO","INFANTIL",IF(B29="BEBE","INFANTIL",IF(B29="HOGAR","HOGAR Y COMPLEMENTOS",IF(B29="COMPLEMENTOS","HOGAR Y COMPLEMENTOS",IF(B29="COLEGIAL","HOGAR Y COMPLEMENTOS",IF(B29="INT MUJER","INTERIOR",IF(B29="INT HOMBRE","INTERIOR",IF(B29="INT NINA","INTERIOR",IF(B29="INT NINO","INTERIOR",IF(B29="INT BEBITA","INTERIOR",IF(B29="INT BEBITO","INTERIOR",IF(B29="MUJER","MUJER",IF(B29="HOMBRE","HOMBRE","")))))))))))))))) -> INFANTIL | V29: Planeación Inicial | AA29: =+CONCATENATE(T29,B29,C29,D29,E29,F29) -> INFANTILBEBITAEXPLORADORDEPORTIVOCONJUNTOBASICO MODA
A30: REF LN FM BTA 49 | B30: BEBITA | C30: EXPLORADOR | D30: DEPORTIVO | E30: CONJUNTO | F30: BASICO MODA | G30: 1 | H30: 12-18 | I30: 1 | J30: 96 | K30: FEBRERO | L30: 45337 | M30: C.I CREYTEX S.A.S | N30: FIRME | O30: 0 | P30: Líneas | Q30: CEDI | R30: BEBITAEXPLORADORDEPORTIVOCONJUNTOBASICO MODA | T30: =+IF(B30="NINA","INFANTIL",IF(B30="NINO","INFANTIL",IF(B30="BEBITA","INFANTIL",IF(B30="BEBITO","INFANTIL",IF(B30="BEBE","INFANTIL",IF(B30="HOGAR","HOGAR Y COMPLEMENTOS",IF(B30="COMPLEMENTOS","HOGAR Y COMPLEMENTOS",IF(B30="COLEGIAL","HOGAR Y COMPLEMENTOS",IF(B30="INT MUJER","INTERIOR",IF(B30="INT HOMBRE","INTERIOR",IF(B30="INT NINA","INTERIOR",IF(B30="INT NINO","INTERIOR",IF(B30="INT BEBITA","INTERIOR",IF(B30="INT BEBITO","INTERIOR",IF(B30="MUJER","MUJER",IF(B30="HOMBRE","HOMBRE","")))))))))))))))) -> INFANTIL | V30: Planeación Inicial | AA30: =+CONCATENATE(T30,B30,C30,D30,E30,F30) -> INFANTILBEBITAEXPLORADORDEPORTIVOCONJUNTOBASICO MODA
A31: REF LN FM BTA 49 | B31: BEBITA | C31: EXPLORADOR | D31: DEPORTIVO | E31: CONJUNTO | F31: BASICO MODA | G31: 1 | H31: 6-12 | I31: 1 | J31: 0 | K31: FEBRERO | L31: 45337 | M31: C.I CREYTEX S.A.S | N31: FIRME | O31: 0 | P31: Líneas | Q31: CEDI | R31: BEBITAEXPLORADORDEPORTIVOCONJUNTOBASICO MODA | T31: =+IF(B31="NINA","INFANTIL",IF(B31="NINO","INFANTIL",IF(B31="BEBITA","INFANTIL",IF(B31="BEBITO","INFANTIL",IF(B31="BEBE","INFANTIL",IF(B31="HOGAR","HOGAR Y COMPLEMENTOS",IF(B31="COMPLEMENTOS","HOGAR Y COMPLEMENTOS",IF(B31="COLEGIAL","HOGAR Y COMPLEMENTOS",IF(B31="INT MUJER","INTERIOR",IF(B31="INT HOMBRE","INTERIOR",IF(B31="INT NINA","INTERIOR",IF(B31="INT NINO","INTERIOR",IF(B31="INT BEBITA","INTERIOR",IF(B31="INT BEBITO","INTERIOR",IF(B31="MUJER","MUJER",IF(B31="HOMBRE","HOMBRE","")))))))))))))))) -> INFANTIL | V31: Planeación Inicial | AA31: =+CONCATENATE(T31,B31,C31,D31,E31,F31) -> INFANTILBEBITAEXPLORADORDEPORTIVOCONJUNTOBASICO MODA
A32: REF LN FM BTA 49 | B32: BEBITA | C32: EXPLORADOR | D32: DEPORTIVO | E32: CONJUNTO | F32: BASICO MODA | G32: 1 | H32: 24-36 | I32: 1 | J32: 114 | K32: FEBRERO | L32: 45337 | M32: C.I CREYTEX S.A.S | N32: FIRME | O32: 0 | P32: Líneas | Q32: CEDI | R32: BEBITAEXPLORADORDEPORTIVOCONJUNTOBASICO MODA | T32: =+IF(B32="NINA","INFANTIL",IF(B32="NINO","INFANTIL",IF(B32="BEBITA","INFANTIL",IF(B32="BEBITO","INFANTIL",IF(B32="BEBE","INFANTIL",IF(B32="HOGAR","HOGAR Y COMPLEMENTOS",IF(B32="COMPLEMENTOS","HOGAR Y COMPLEMENTOS",IF(B32="COLEGIAL","HOGAR Y COMPLEMENTOS",IF(B32="INT MUJER","INTERIOR",IF(B32="INT HOMBRE","INTERIOR",IF(B32="INT NINA","INTERIOR",IF(B32="INT NINO","INTERIOR",IF(B32="INT BEBITA","INTERIOR",IF(B32="INT BEBITO","INTERIOR",IF(B32="MUJER","MUJER",IF(B32="HOMBRE","HOMBRE","")))))))))))))))) -> INFANTIL | V32: Planeación Inicial | AA32: =+CONCATENATE(T32,B32,C32,D32,E32,F32) -> INFANTILBEBITAEXPLORADORDEPORTIVOCONJUNTOBASICO MODA
A33: REF LN FM BTA 42 | B33: BEBITA | C33: EXPLORADOR | D33: DEPORTIVO | E33: CAMISETA | F33: BASICO MODA | G33: 1 | H33: 18-24 | I33: 1 | J33: 138 | K33: FEBRERO | L33: 45341 | M33: CONFETEX DE COLOMBIA SAS | N33: FIRME | O33: 0 | P33: Líneas | Q33: CEDI | R33: BEBITAEXPLORADORDEPORTIVOCAMISETABASICO MODA | T33: =+IF(B33="NINA","INFANTIL",IF(B33="NINO","INFANTIL",IF(B33="BEBITA","INFANTIL",IF(B33="BEBITO","INFANTIL",IF(B33="BEBE","INFANTIL",IF(B33="HOGAR","HOGAR Y COMPLEMENTOS",IF(B33="COMPLEMENTOS","HOGAR Y COMPLEMENTOS",IF(B33="COLEGIAL","HOGAR Y COMPLEMENTOS",IF(B33="INT MUJER","INTERIOR",IF(B33="INT HOMBRE","INTERIOR",IF(B33="INT NINA","INTERIOR",IF(B33="INT NINO","INTERIOR",IF(B33="INT BEBITA","INTERIOR",IF(B33="INT BEBITO","INTERIOR",IF(B33="MUJER","MUJER",IF(B33="HOMBRE","HOMBRE","")))))))))))))))) -> INFANTIL | V33: Planeación Inicial | AA33: =+CONCATENATE(T33,B33,C33,D33,E33,F33) -> INFANTILBEBITAEXPLORADORDEPORTIVOCAMISETABASICO MODA
A34: REF LN FM BTA 42 | B34: BEBITA | C34: EXPLORADOR | D34: DEPORTIVO | E34: CAMISETA | F34: BASICO MODA | G34: 1 | H34: 12-18 | I34: 1 | J34: 87 | K34: FEBRERO | L34: 45341 | M34: CONFETEX DE COLOMBIA SAS | N34: FIRME | O34: 0 | P34: Líneas | Q34: CEDI | R34: BEBITAEXPLORADORDEPORTIVOCAMISETABASICO MODA | T34: =+IF(B34="NINA","INFANTIL",IF(B34="NINO","INFANTIL",IF(B34="BEBITA","INFANTIL",IF(B34="BEBITO","INFANTIL",IF(B34="BEBE","INFANTIL",IF(B34="HOGAR","HOGAR Y COMPLEMENTOS",IF(B34="COMPLEMENTOS","HOGAR Y COMPLEMENTOS",IF(B34="COLEGIAL","HOGAR Y COMPLEMENTOS",IF(B34="INT MUJER","INTERIOR",IF(B34="INT HOMBRE","INTERIOR",IF(B34="INT NINA","INTERIOR",IF(B34="INT NINO","INTERIOR",IF(B34="INT BEBITA","INTERIOR",IF(B34="INT BEBITO","INTERIOR",IF(B34="MUJER","MUJER",IF(B34="HOMBRE","HOMBRE","")))))))))))))))) -> INFANTIL | V34: Planeación Inicial | AA34: =+CONCATENATE(T34,B34,C34,D34,E34,F34) -> INFANTILBEBITAEXPLORADORDEPORTIVOCAMISETABASICO MODA
A35: REF LN FM BTA 42 | B35: BEBITA | C35: EXPLORADOR | D35: DEPORTIVO | E35: CAMISETA | F35: BASICO MODA | G35: 1 | H35: 6-12 | I35: 1 | J35: 85 | K35: FEBRERO | L35: 45341 | M35: CONFETEX DE COLOMBIA SAS | N35: FIRME | O35: 0 | P35: Líneas | Q35: CEDI | R35: BEBITAEXPLORADORDEPORTIVOCAMISETABASICO MODA | T35: =+IF(B35="NINA","INFANTIL",IF(B35="NINO","INFANTIL",IF(B35="BEBITA","INFANTIL",IF(B35="BEBITO","INFANTIL",IF(B35="BEBE","INFANTIL",IF(B35="HOGAR","HOGAR Y COMPLEMENTOS",IF(B35="COMPLEMENTOS","HOGAR Y COMPLEMENTOS",IF(B35="COLEGIAL","HOGAR Y COMPLEMENTOS",IF(B35="INT MUJER","INTERIOR",IF(B35="INT HOMBRE","INTERIOR",IF(B35="INT NINA","INTERIOR",IF(B35="INT NINO","INTERIOR",IF(B35="INT BEBITA","INTERIOR",IF(B35="INT BEBITO","INTERIOR",IF(B35="MUJER","MUJER",IF(B35="HOMBRE","HOMBRE","")))))))))))))))) -> INFANTIL | V35: Planeación Inicial | AA35: =+CONCATENATE(T35,B35,C35,D35,E35,F35) -> INFANTILBEBITAEXPLORADORDEPORTIVOCAMISETABASICO MODA
A36: REF LN FM BTA 42 | B36: BEBITA | C36: EXPLORADOR | D36: DEPORTIVO | E36: CAMISETA | F36: BASICO MODA | G36: 1 | H36: 24-36 | I36: 1 | J36: 134 | K36: FEBRERO | L36: 45341 | M36: CONFETEX DE COLOMBIA SAS | N36: FIRME | O36: 0 | P36: Líneas | Q36: CEDI | R36: BEBITAEXPLORADORDEPORTIVOCAMISETABASICO MODA | T36: =+IF(B36="NINA","INFANTIL",IF(B36="NINO","INFANTIL",IF(B36="BEBITA","INFANTIL",IF(B36="BEBITO","INFANTIL",IF(B36="BEBE","INFANTIL",IF(B36="HOGAR","HOGAR Y COMPLEMENTOS",IF(B36="COMPLEMENTOS","HOGAR Y COMPLEMENTOS",IF(B36="COLEGIAL","HOGAR Y COMPLEMENTOS",IF(B36="INT MUJER","INTERIOR",IF(B36="INT HOMBRE","INTERIOR",IF(B36="INT NINA","INTERIOR",IF(B36="INT NINO","INTERIOR",IF(B36="INT BEBITA","INTERIOR",IF(B36="INT BEBITO","INTERIOR",IF(B36="MUJER","MUJER",IF(B36="HOMBRE","HOMBRE","")))))))))))))))) -> INFANTIL | V36: Planeación Inicial | AA36: =+CONCATENATE(T36,B36,C36,D36,E36,F36) -> INFANTILBEBITAEXPLORADORDEPORTIVOCAMISETABASICO MODA
A37: REF LN FM BTA 43 | B37: BEBITA | C37: EXPLORADOR | D37: DEPORTIVO | E37: CAMISETA | F37: BASICO MODA | G37: 1 | H37: 18-24 | I37: 1 | J37: 138 | K37: FEBRERO | L37: 45341 | M37: CONFETEX DE COLOMBIA SAS | N37: FIRME | O37: 0 | P37: Líneas | Q37: CEDI | R37: BEBITAEXPLORADORDEPORTIVOCAMISETABASICO MODA | T37: =+IF(B37="NINA","INFANTIL",IF(B37="NINO","INFANTIL",IF(B37="BEBITA","INFANTIL",IF(B37="BEBITO","INFANTIL",IF(B37="BEBE","INFANTIL",IF(B37="HOGAR","HOGAR Y COMPLEMENTOS",IF(B37="COMPLEMENTOS","HOGAR Y COMPLEMENTOS",IF(B37="COLEGIAL","HOGAR Y COMPLEMENTOS",IF(B37="INT MUJER","INTERIOR",IF(B37="INT HOMBRE","INTERIOR",IF(B37="INT NINA","INTERIOR",IF(B37="INT NINO","INTERIOR",IF(B37="INT BEBITA","INTERIOR",IF(B37="INT BEBITO","INTERIOR",IF(B37="MUJER","MUJER",IF(B37="HOMBRE","HOMBRE","")))))))))))))))) -> INFANTIL | V37: Planeación Inicial | AA37: =+CONCATENATE(T37,B37,C37,D37,E37,F37) -> INFANTILBEBITAEXPLORADORDEPORTIVOCAMISETABASICO MODA
A38: REF LN FM BTA 43 | B38: BEBITA | C38: EXPLORADOR | D38: DEPORTIVO | E38: CAMISETA | F38: BASICO MODA | G38: 1 | H38: 12-18 | I38: 1 | J38: 87 | K38: FEBRERO | L38: 45341 | M38: CONFETEX DE COLOMBIA SAS | N38: FIRME | O38: 0 | P38: Líneas | Q38: CEDI | R38: BEBITAEXPLORADORDEPORTIVOCAMISETABASICO MODA | T38: =+IF(B38="NINA","INFANTIL",IF(B38="NINO","INFANTIL",IF(B38="BEBITA","INFANTIL",IF(B38="BEBITO","INFANTIL",IF(B38="BEBE","INFANTIL",IF(B38="HOGAR","HOGAR Y COMPLEMENTOS",IF(B38="COMPLEMENTOS","HOGAR Y COMPLEMENTOS",IF(B38="COLEGIAL","HOGAR Y COMPLEMENTOS",IF(B38="INT MUJER","INTERIOR",IF(B38="INT HOMBRE","INTERIOR",IF(B38="INT NINA","INTERIOR",IF(B38="INT NINO","INTERIOR",IF(B38="INT BEBITA","INTERIOR",IF(B38="INT BEBITO","INTERIOR",IF(B38="MUJER","MUJER",IF(B38="HOMBRE","HOMBRE","")))))))))))))))) -> INFANTIL | V38: Planeación Inicial | AA38: =+CONCATENATE(T38,B38,C38,D38,E38,F38) -> INFANTILBEBITAEXPLORADORDEPORTIVOCAMISETABASICO MODA
A39: REF LN FM BTA 43 | B39: BEBITA | C39: EXPLORADOR | D39: DEPORTIVO | E39: CAMISETA | F39: BASICO MODA | G39: 1 | H39: 6-12 | I39: 1 | J39: 85 | K39: FEBRERO | L39: 45341 | M39: CONFETEX DE COLOMBIA SAS | N39: FIRME | O39: 0 | P39: Líneas | Q39: CEDI | R39: BEBITAEXPLORADORDEPORTIVOCAMISETABASICO MODA | T39: =+IF(B39="NINA","INFANTIL",IF(B39="NINO","INFANTIL",IF(B39="BEBITA","INFANTIL",IF(B39="BEBITO","INFANTIL",IF(B39="BEBE","INFANTIL",IF(B39="HOGAR","HOGAR Y COMPLEMENTOS",IF(B39="COMPLEMENTOS","HOGAR Y COMPLEMENTOS",IF(B39="COLEGIAL","HOGAR Y COMPLEMENTOS",IF(B39="INT MUJER","INTERIOR",IF(B39="INT HOMBRE","INTERIOR",IF(B39="INT NINA","INTERIOR",IF(B39="INT NINO","INTERIOR",IF(B39="INT BEBITA","INTERIOR",IF(B39="INT BEBITO","INTERIOR",IF(B39="MUJER","MUJER",IF(B39="HOMBRE","HOMBRE","")))))))))))))))) -> INFANTIL | V39: Planeación Inicial | AA39: =+CONCATENATE(T39,B39,C39,D39,E39,F39) -> INFANTILBEBITAEXPLORADORDEPORTIVOCAMISETABASICO MODA
A40: REF LN FM BTA 43 | B40: BEBITA | C40: EXPLORADOR | D40: DEPORTIVO | E40: CAMISETA | F40: BASICO MODA | G40: 1 | H40: 24-36 | I40: 1 | J40: 134 | K40: FEBRERO | L40: 45341 | M40: CONFETEX DE COLOMBIA SAS | N40: FIRME | O40: 0 | P40: Líneas | Q40: CEDI | R40: BEBITAEXPLORADORDEPORTIVOCAMISETABASICO MODA | T40: =+IF(B40="NINA","INFANTIL",IF(B40="NINO","INFANTIL",IF(B40="BEBITA","INFANTIL",IF(B40="BEBITO","INFANTIL",IF(B40="BEBE","INFANTIL",IF(B40="HOGAR","HOGAR Y COMPLEMENTOS",IF(B40="COMPLEMENTOS","HOGAR Y COMPLEMENTOS",IF(B40="COLEGIAL","HOGAR Y COMPLEMENTOS",IF(B40="INT MUJER","INTERIOR",IF(B40="INT HOMBRE","INTERIOR",IF(B40="INT NINA","INTERIOR",IF(B40="INT NINO","INTERIOR",IF(B40="INT BEBITA","INTERIOR",IF(B40="INT BEBITO","INTERIOR",IF(B40="MUJER","MUJER",IF(B40="HOMBRE","HOMBRE","")))))))))))))))) -> INFANTIL | V40: Planeación Inicial | AA40: =+CONCATENATE(T40,B40,C40,D40,E40,F40) -> INFANTILBEBITAEXPLORADORDEPORTIVOCAMISETABASICO MODA
... A52: REF LN FM BTA 51 | B52: BEBITA | C52: EXPLORADOR | D52: DEPORTIVO | E52: VESTIDO | F52: BASICO MODA | G52: 1 | H52: 24-36 | I52: 1 | J52: 74 | K52: FEBRERO | L52: 45341 | M52: CONFETEX DE COLOMBIA SAS | N52: FIRME | O52: 0 | P52: Líneas | Q52: CEDI | R52: BEBITAEXPLORADORDEPORTIVOVESTIDOBASICO MODA | T52: =+IF(B52="NINA","INFANTIL",IF(B52="NINO","INFANTIL",IF(B52="BEBITA","INFANTIL",IF(B52="BEBITO","INFANTIL",IF(B52="BEBE","INFANTIL",IF(B52="HOGAR","HOGAR Y COMPLEMENTOS",IF(B52="COMPLEMENTOS","HOGAR Y COMPLEMENTOS",IF(B52="COLEGIAL","HOGAR Y COMPLEMENTOS",IF(B52="INT MUJER","INTERIOR",IF(B52="INT HOMBRE","INTERIOR",IF(B52="INT NINA","INTERIOR",IF(B52="INT NINO","INTERIOR",IF(B52="INT BEBITA","INTERIOR",IF(B52="INT BEBITO","INTERIOR",IF(B52="MUJER","MUJER",IF(B52="HOMBRE","HOMBRE","")))))))))))))))) -> INFANTIL | V52: Planeación Inicial | AA52: =+CONCATENATE(T52,B52,C52,D52,E52,F52) -> INFANTILBEBITAEXPLORADORDEPORTIVOVESTIDOBASICO MODA
A53: REF PDP 1T22 | B53: BEBITA | C53: DORMILON | D53: DEPORTIVO | E53: MAMELUCO | F53: BASICO MODA | G53: 1 | H53: 0-6 | I53: NA | J53: 0 | K53: FEBRERO | L53: 45344 | M53: CONFETEX DE COLOMBIA SAS | N53: VMI | O53: 11950 | P53: PDP | Q53: CEDI | R53: BEBITADORMILONDEPORTIVOMAMELUCOBASICO MODA | S53: SE COMPRO EN ENERO PARA HACER CURVA EN FIRME | T53: =+IF(B53="NINA","INFANTIL",IF(B53="NINO","INFANTIL",IF(B53="BEBITA","INFANTIL",IF(B53="BEBITO","INFANTIL",IF(B53="BEBE","INFANTIL",IF(B53="HOGAR","HOGAR Y COMPLEMENTOS",IF(B53="COMPLEMENTOS","HOGAR Y COMPLEMENTOS",IF(B53="COLEGIAL","HOGAR Y COMPLEMENTOS",IF(B53="INT MUJER","INTERIOR",IF(B53="INT HOMBRE","INTERIOR",IF(B53="INT NINA","INTERIOR",IF(B53="INT NINO","INTERIOR",IF(B53="INT BEBITA","INTERIOR",IF(B53="INT BEBITO","INTERIOR",IF(B53="MUJER","MUJER",IF(B53="HOMBRE","HOMBRE","")))))))))))))))) -> INFANTIL | V53: Planeación Inicial | AA53: =+CONCATENATE(T53,B53,C53,D53,E53,F53) -> INFANTILBEBITADORMILONDEPORTIVOMAMELUCOBASICO MODA
A54: REF PDP 1T22 | B54: BEBITA | C54: DORMILON | D54: DEPORTIVO | E54: MAMELUCO | F54: BASICO MODA | G54: 1 | H54: 6-12 | I54: NA | J54: 0 | K54: FEBRERO | L54: 45344 | M54: CONFETEX DE COLOMBIA SAS | N54: VMI | O54: 11950 | P54: PDP | Q54: CEDI | R54: BEBITADORMILONDEPORTIVOMAMELUCOBASICO MODA | S54: SE COMPRO EN ENERO PARA HACER CURVA EN FIRME | T54: =+IF(B54="NINA","INFANTIL",IF(B54="NINO","INFANTIL",IF(B54="BEBITA","INFANTIL",IF(B54="BEBITO","INFANTIL",IF(B54="BEBE","INFANTIL",IF(B54="HOGAR","HOGAR Y COMPLEMENTOS",IF(B54="COMPLEMENTOS","HOGAR Y COMPLEMENTOS",IF(B54="COLEGIAL","HOGAR Y COMPLEMENTOS",IF(B54="INT MUJER","INTERIOR",IF(B54="INT HOMBRE","INTERIOR",IF(B54="INT NINA","INTERIOR",IF(B54="INT NINO","INTERIOR",IF(B54="INT BEBITA","INTERIOR",IF(B54="INT BEBITO","INTERIOR",IF(B54="MUJER","MUJER",IF(B54="HOMBRE","HOMBRE","")))))))))))))))) -> INFANTIL | V54: Planeación Inicial | AA54: =+CONCATENATE(T54,B54,C54,D54,E54,F54) -> INFANTILBEBITADORMILONDEPORTIVOMAMELUCOBASICO MODA
...

Sheet Hoja1
L2: 153636 | M2: BOCANEGRA MARIA ELENA
B3: Mes | C3: Desc. Prov. | D3: Categoría | E3: Codigo | F3: Suma de Cantidad | G3: FECHA | L3: 271816 | M3: BOCANEGRA MARIA ELENA
A4: =+CONCATENATE(C4,E4,B4) -> -REF LN FM BTA 1ENERO | B4: ENERO | C4: - | D4: BEBITA | E4: REF LN FM BTA 1 | F4: 703 | L4: 296854 | M4: BRIO IN SAS
A5: =+CONCATENATE(C5,E5,B5) -> -REF LN FM BTA 10ENERO | B5: ENERO | C5: - | D5: BEBITA | E5: REF LN FM BTA 10 | F5: 122 | L5: 269722 | M5: CALCETERIA JCL LTDA
A6: =+CONCATENATE(C6,E6,B6) -> -REF LN FM BTA 11ENERO | B6: ENERO | C6: - | D6: BEBITA | E6: REF LN FM BTA 11 | F6: 91 | L6: 265228 | M6: CONSUELO DEL ZULUAGA RAMIREZ
A7: =+CONCATENATE(C7,E7,B7) -> -REF LN FM BTA 12ENERO | B7: ENERO | C7: - | D7: BEBITA | E7: REF LN FM BTA 12 | F7: 175 | L7: 249981 | M7: CONSUELO DEL ZULUAGA RAMIREZ
A8: =+CONCATENATE(C8,E8,B8) -> -REF LN FM BTA 13ENERO | B8: ENERO | C8: - | D8: BEBITA | E8: REF LN FM BTA 13 | F8: 268 | L8: 249982 | M8: CONSUELO DEL ZULUAGA RAMIREZ
A9: =+CONCATENATE(C9,E9,B9) -> -REF LN FM BTA 14ENERO | B9: ENERO | C9: - | D9: BEBITA | E9: REF LN FM BTA 14 | F9: 321 | L9: 270242 | M9: CONSUELO DEL ZULUAGA RAMIREZ
A10: =+CONCATENATE(C10,E10,B10) -> -REF LN FM BTA 15ENERO | B10: ENERO | C10: - | D10: BEBITA | E10: REF LN FM BTA 15 | F10: 487 | L10: 272038 | M10: CONSUELO DEL ZULUAGA RAMIREZ
A11: =+CONCATENATE(C11,E11,B11) -> -REF LN FM BTA 16ENERO | B11: ENERO | C11: - | D11: BEBITA | E11: REF LN FM BTA 16 | F11: 164 | L11: 272035 | M11: CONSUELO DEL ZULUAGA RAMIREZ
A12: =+CONCATENATE(C12,E12,B12) -> -REF LN FM BTA 17ENERO | B12: ENERO | C12: - | D12: BEBITA | E12: REF LN FM BTA 17 | F12: 146 | L12: 272036 | M12: CONSUELO DEL ZULUAGA RAMIREZ
A13: =+CONCATENATE(C13,E13,B13) -> -REF LN FM BTA 18ENERO | B13: ENERO | C13: - | D13: BEBITA | E13: REF LN FM BTA 18 | F13: 398 | L13: 272037 | M13: CONSUELO DEL ZULUAGA RAMIREZ
A14: =+CONCATENATE(C14,E14,B14) -> -REF LN FM BTA 19ENERO | B14: ENERO | C14: - | D14: BEBITA | E14: REF LN FM BTA 19 | F14: 398 | L14: 291133 | M14: CREACIONES DURATEX S.A.S.
A15: =+CONCATENATE(C15,E15,B15) -> -REF LN FM BTA 2ENERO | B15: ENERO | C15: - | D15: BEBITA | E15: REF LN FM BTA 2 | F15: 702 | L15: 294701 | M15: CREACIONES DURATEX S.A.S.
... A36: =+CONCATENATE(C36,E36,B36) -> -REF PDP FM BTA 7ENERO | B36: ENERO | C36: - | D36: BEBITA | E36: REF PDP FM BTA 7 | F36: 521 | L36: 294380 | M36: GRUPO SAKA SAS
A37: =+CONCATENATE(C37,E37,B37) -> ALZATE GIRALDO ANGELA MARIBEL Y/O ALZATE GRIRALDO GABRIELA ORFANY269539ENERO | B37: ENERO | C37: ALZATE GIRALDO ANGELA MARIBEL Y/O ALZATE GRIRALDO GABRIELA ORFANY | D37: BEBITA | E37: 269539 | F37: 212 | G37: 45302 | L37: 242516 | M37: INVERSIONES ACEVEDO CORTES SAS
A38: =+CONCATENATE(C38,E38,B38) -> ALZATE GIRALDO ANGELA MARIBEL Y/O ALZATE GRIRALDO GABRIELA ORFANY309253ENERO | B38: ENERO | C38: ALZATE GIRALDO ANGELA MARIBEL Y/O ALZATE GRIRALDO GABRIELA ORFANY | D38: BEBITA | E38: 309253 | F38: 37 | G38: 45302 | L38: 242518 | M38: INVERSIONES ACEVEDO CORTES SAS
A39: =+CONCATENATE(C39,E39,B39) -> CONFETEX DE COLOMBIA SASREF PDP 1T3ENERO | B39: ENERO | C39: CONFETEX DE COLOMBIA SAS | D39: BEBITA | E39: REF PDP 1T3 | F39: 93 | G39: 45303 | L39: 181203 | M39: TERESA DEL BETANCUR BETANCUR
A40: =+CONCATENATE(C40,E40,B40) -> CONFETEX DE COLOMBIA SASREF PDP 1T4ENERO | B40: ENERO | C40: CONFETEX DE COLOMBIA SAS | D40: BEBITA | E40: REF PDP 1T4 | F40: 604 | G40: 45303 | L40: 271933 | M40: TERESA DEL BETANCUR BETANCUR
A41: =+CONCATENATE(C41,E41,B41) -> CONFETEX DE COLOMBIA SASREF PDP 1T5ENERO | B41: ENERO | C41: CONFETEX DE COLOMBIA SAS | D41: BEBITA | E41: REF PDP 1T5 | F41: 477 | G41: 45303
A42: =+CONCATENATE(C42,E42,B42) -> CONFETEX DE COLOMBIA SASREF PDP 1T6ENERO | B42: ENERO | C42: CONFETEX DE COLOMBIA SAS | D42: BEBITA | E42: REF PDP 1T6 | F42: 289 | G42: 45303
A43: =+CONCATENATE(C43,E43,B43) -> CONFETEX DE COLOMBIA SASREF PDP 1T7ENERO | B43: ENERO | C43: CONFETEX DE COLOMBIA SAS | D43: BEBITA | E43: REF PDP 1T7 | F43: 860 | G43: 45303
A44: =+CONCATENATE(C44,E44,B44) -> FOR BABYS -INFORKIDS311375ENERO | B44: ENERO | C44: FOR BABYS -INFORKIDS | D44: BEBITA | E44: 311375 | F44: 34 | G44: 45306
A45: =+CONCATENATE(C45,E45,B45) -> FOR BABYS -INFORKIDS311377ENERO | B45: ENERO | C45: FOR BABYS -INFORKIDS | D45: BEBITA | E45: 311377 | F45: 225 | G45: 45306
A46: =+CONCATENATE(C46,E46,B46) -> FOR BABYS -INFORKIDS311379ENERO | B46: ENERO | C46: FOR BABYS -INFORKIDS | D46: BEBITA | E46: 311379 | F46: 14 | G46: 45306
A47: =+CONCATENATE(C47,E47,B47) -> GONZALES COLMENARES RICHARD PASTOR311713ENERO | B47: ENERO | C47: GONZALES COLMENARES RICHARD PASTOR | D47: BEBITA | E47: 311713 | F47: 262 | G47: 45306
A48: =+CONCATENATE(C48,E48,B48) -> INDUSTRIAS CHICCO SAS301995ENERO | B48: ENERO | C48: INDUSTRIAS CHICCO SAS | D48: BEBITA | E48: 301995 | F48: 987 | G48: 45307
A49: =+CONCATENATE(C49,E49,B49) -> INDUSTRIAS CHICCO SAS305544ENERO | B49: ENERO | C49: INDUSTRIAS CHICCO SAS | D49: BEBITA | E49: 305544 | F49: 409 | G49: 45307
A50: =+CONCATENATE(C50,E50,B50) -> INFORKIDS302288ENERO | B50: ENERO | C50: INFORKIDS | D50: BEBITA | E50: 302288 | F50: 26 | G50: 45308
A51: =+CONCATENATE(C51,E51,B51) -> INFORKIDS311633ENERO | B51: ENERO | C51: INFORKIDS | D51: BEBITA | E51: 311633 | F51: 79 | G51: 45308
A52: =+CONCATENATE(C52,E52,B52) -> INFORKIDS311636ENERO | B52: ENERO | C52: INFORKIDS | D52: BEBITA | E52: 311636 | F52: 118 | G52: 45308
A53: =+CONCATENATE(C53,E53,B53) -> INFORKIDS311637ENERO | B53: ENERO | C53: INFORKIDS | D53: BEBITA | E53: 311637 | F53: 55 | G53: 45308
A54: =+CONCATENATE(C54,E54,B54) -> INFORKIDS311638ENERO | B54: ENERO | C54: INFORKIDS | D54: BEBITA | E54: 311638 | F54: 45 | G54: 45308
A55: =+CONCATENATE(C55,E55,B55) -> INFORKIDS311639ENERO | B55: ENERO | C55: INFORKIDS | D55: BEBITA | E55: 311639 | F55: 97 | G55: 45308
... A60: =+CONCATENATE(C60,E60,B60) -> TEJIDOS Y CONFECCIONES GERPAR S.A (EN CONSIGNACION)311946ENERO | B60: ENERO | C60: TEJIDOS Y CONFECCIONES GERPAR S.A (EN CONSIGNACION) | D60: BEBITA | E60: 311946 | F60: 19 | G60: 45309

Sheet Febrero
B3: CATEGORÍAS | C3: Sem 5 | D3: Sem 6 | E3: Sem 7 | F3: Sem 8 | G3: Sem 9 | H3: TOTAL
B4: MUJER | C4: =SUM(C13:D13) -> 6764 | D4: =SUM(E13:I13) -> 33024 | E4: =SUM(J13:N13) -> 33050 | F4: =SUM(O13:S13) -> 20497 | H4: =+SUM(C4:G4) -> 93335
B5: INTERIOR | C5: =SUM(C14:D14) -> 19098 | D5: =SUM(E14:I14) -> 36294 | E5: =SUM(J14:N14) -> 63838 | F5: =SUM(O14:S14) -> 143219 | H5: =+SUM(C5:G5) -> 262449
B6: HOMBRE | C6: =SUM(C15:D15) -> 447 | D6: =SUM(E15:I15) -> 10321 | E6: =SUM(J15:N15) -> 8516 | F6: =SUM(O15:S15) -> 11540 | H6: =+SUM(C6:G6) -> 30824
B7: INFANTIL | C7: =SUM(C16:D16) -> 3570 | D7: =SUM(E16:I16) -> 19733 | E7: =SUM(J16:N16) -> 12372 | F7: =SUM(O16:S16) -> 23976 | H7: =+SUM(C7:G7) -> 59651
B8: HOGAR Y COMPLEMENTOS | C8: =SUM(C17:D17) -> 2744 | D8: =SUM(E17:I17) -> 8610 | E8: =SUM(J17:N17) -> 4987 | F8: =SUM(O17:S17) -> 31868 | H8: =+SUM(C8:G8) -> 48209
B9: TOTAL | C9: =SUM(C4:C8) -> 32623 | D9: =SUM(D4:D8) -> 107982 | E9: =SUM(E4:E8) -> 122763 | F9: =SUM(F4:F8) -> 231100 | G9: =SUM(G4:G8) -> 0 | H9: =SUM(C9:G9) -> 494468
B11: TIENDAS | C11: Jueves | D11: Viernes | E11: Lunes | F11: Martes | G11: Miércoles | H11: Jueves | I11: Viernes | J11: Lunes | K11: Martes | L11: Miércoles | M11: Jueves | N11: Viernes | O11: Lunes | P11: Martes | Q11: Miércoles | R11: Jueves | S11: Viernes | T11: Lunes
B12: CATEGORÍAS | C12: 45323 | D12: 45324 | E12: 45327 | F12: 45328 | G12: 45329 | H12: 45330 | I12: 45331 | J12: 45334 | K12: 45335 | L12: 45336 | M12: 45337 | N12: 45338 | O12: 45341 | P12: 45342 | Q12: 45343 | R12: 45344 | S12: 45345 | U12: - | V12: - | W12: TOTAL
B13: MUJER | C13: =SUMIFS(Consolidado!$J:$J,Consolidado!$T:$T,Febrero!$B13,Consolidado!$L:$L,Febrero!C$21,Consolidado!$Q:$Q,Febrero!$B$11)+C22 -> 1728 | D13: =SUMIFS(Consolidado!$J:$J,Consolidado!$T:$T,Febrero!$B13,Consolidado!$L:$L,Febrero!D$21,Consolidado!$Q:$Q,Febrero!$B$11)+D22 -> 5036 | E13: =SUMIFS(Consolidado!$J:$J,Consolidado!$T:$T,Febrero!$B13,Consolidado!$L:$L,Febrero!E$21,Consolidado!$Q:$Q,Febrero!$B$11)+E22 -> 5413 | F13: =SUMIFS(Consolidado!$J:$J,Consolidado!$T:$T,Febrero!$B13,Consolidado!$L:$L,Febrero!F$21,Consolidado!$Q:$Q,Febrero!$B$11)+F22 -> 344 | G13: =SUMIFS(Consolidado!$J:$J,Consolidado!$T:$T,Febrero!$B13,Consolidado!$L:$L,Febrero!G$21,Consolidado!$Q:$Q,Febrero!$B$11)+G22 -> 7894 | H13: =SUMIFS(Consolidado!$J:$J,Consolidado!$T:$T,Febrero!$B13,Consolidado!$L:$L,Febrero!H$21,Consolidado!$Q:$Q,Febrero!$B$11)+H22 -> 13627 | I13: =SUMIFS(Consolidado!$J:$J,Consolidado!$T:$T,Febrero!$B13,Consolidado!$L:$L,Febrero!I$21,Consolidado!$Q:$Q,Febrero!$B$11)+I22 -> 5746 | J13: =SUMIFS(Consolidado!$J:$J,Consolidado!$T:$T,Febrero!$B13,Consolidado!$L:$L,Febrero!J$21,Consolidado!$Q:$Q,Febrero!$B$11)+J22 -> 7962 | ... S13: =SUMIFS(Consolidado!$J:$J,Consolidado!$T:$T,Febrero!$B13,Consolidado!$L:$L,Febrero!S$21,Consolidado!$Q:$Q,Febrero!$B$11)+S22 -> 5296 | U13: =SUMIFS(Consolidado!$J:$J,Consolidado!$T:$T,Febrero!$B13,Consolidado!$L:$L,Febrero!U$21,Consolidado!$Q:$Q,Febrero!$B$11)+U22 -> 0 | V13: =SUMIFS(Consolidado!$J:$J,Consolidado!$T:$T,Febrero!$B13,Consolidado!$L:$L,Febrero!V$21,Consolidado!$Q:$Q,Febrero!$B$11)+V22 -> 0 | W13: =+SUM(C13:V13) -> 93335
B14: INTERIOR | C14: =SUMIFS(Consolidado!$J:$J,Consolidado!$T:$T,Febrero!$B14,Consolidado!$L:$L,Febrero!C$21,Consolidado!$Q:$Q,Febrero!$B$11)+SUM(C23:C27) -> 19098 | D14: =SUMIFS(Consolidado!$J:$J,Consolidado!$T:$T,Febrero!$B14,Consolidado!$L:$L,Febrero!D$21,Consolidado!$Q:$Q,Febrero!$B$11)+SUM(D23:D27) -> 0 | E14: =SUMIFS(Consolidado!$J:$J,Consolidado!$T:$T,Febrero!$B14,Consolidado!$L:$L,Febrero!E$21,Consolidado!$Q:$Q,Febrero!$B$11)+SUM(E23:E27) -> 5674 | F14: =SUMIFS(Consolidado!$J:$J,Consolidado!$T:$T,Febrero!$B14,Consolidado!$L:$L,Febrero!F$21,Consolidado!$Q:$Q,Febrero!$B$11)+SUM(F23:F27) -> 10619 | G14: =SUMIFS(Consolidado!$J:$J,Consolidado!$T:$T,Febrero!$B14,Consolidado!$L:$L,Febrero!G$21,Consolidado!$Q:$Q,Febrero!$B$11)+SUM(G23:G27) -> 3179 | H14: =SUMIFS(Consolidado!$J:$J,Consolidado!$T:$T,Febrero!$B14,Consolidado!$L:$L,Febrero!H$21,Consolidado!$Q:$Q,Febrero!$B$11)+SUM(H23:H27) -> 5553 | I14: =SUMIFS(Consolidado!$J:$J,Consolidado!$T:$T,Febrero!$B14,Consolidado!$L:$L,Febrero!I$21,Consolidado!$Q:$Q,Febrero!$B$11)+SUM(I23:I27) -> 11269 | J14: =SUMIFS(Consolidado!$J:$J,Consolidado!$T:$T,Febrero!$B14,Consolidado!$L:$L,Febrero!J$21,Consolidado!$Q:$Q,Febrero!$B$11)+SUM(J23:J27) -> 9623 | ... S14: =SUMIFS(Consolidado!$J:$J,Consolidado!$T:$T,Febrero!$B14,Consolidado!$L:$L,Febrero!S$21,Consolidado!$Q:$Q,Febrero!$B$11)+SUM(S23:S27) -> 76131 | U14: =SUMIFS(Consolidado!$J:$J,Consolidado!$T:$T,Febrero!$B14,Consolidado!$L:$L,Febrero!U$21,Consolidado!$Q:$Q,Febrero!$B$11)+SUM(U23:U27) -> 0 | V14: =SUMIFS(Consolidado!$J:$J,Consolidado!$T:$T,Febrero!$B14,Consolidado!$L:$L,Febrero!V$21,Consolidado!$Q:$Q,Febrero!$B$11)+SUM(V23:V27) -> 0 | W14: =+SUM(C14:V14) -> 262449
B15: HOMBRE | C15: =SUMIFS(Consolidado!$J:$J,Consolidado!$T:$T,Febrero!$B15,Consolidado!$L:$L,Febrero!C$21,Consolidado!$Q:$Q,Febrero!$B$11)+C28 -> 104 | D15: =SUMIFS(Consolidado!$J:$J,Consolidado!$T:$T,Febrero!$B15,Consolidado!$L:$L,Febrero!D$21,Consolidado!$Q:$Q,Febrero!$B$11)+D28 -> 343 | E15: =SUMIFS(Consolidado!$J:$J,Consolidado!$T:$T,Febrero!$B15,Consolidado!$L:$L,Febrero!E$21,Consolidado!$Q:$Q,Febrero!$B$11)+E28 -> 0 | F15: =SUMIFS(Consolidado!$J:$J,Consolidado!$T:$T,Febrero!$B15,Consolidado!$L:$L,Febrero!F$21,Consolidado!$Q:$Q,Febrero!$B$11)+F28 -> 732 | G15: =SUMIFS(Consolidado!$J:$J,Consolidado!$T:$T,Febrero!$B15,Consolidado!$L:$L,Febrero!G$21,Consolidado!$Q:$Q,Febrero!$B$11)+G28 -> 916 | H15: =SUMIFS(Consolidado!$J:$J,Consolidado!$T:$T,Febrero!$B15,Consolidado!$L:$L,Febrero!H$21,Consolidado!$Q:$Q,Febrero!$B$11)+H28 -> 4111 | I15: =SUMIFS(Consolidado!$J:$J,Consolidado!$T:$T,Febrero!$B15,Consolidado!$L:$L,Febrero!I$21,Consolidado!$Q:$Q,Febrero!$B$11)+I28 -> 4562 | J15: =SUMIFS(Consolidado!$J:$J,Consolidado!$T:$T,Febrero!$B15,Consolidado!$L:$L,Febrero!J$21,Consolidado!$Q:$Q,Febrero!$B$11)+J28 -> 197 | ... S15: =SUMIFS(Consolidado!$J:$J,Consolidado!$T:$T,Febrero!$B15,Consolidado!$L:$L,Febrero!S$21,Consolidado!$Q:$Q,Febrero!$B$11)+S28 -> 4527 | U15: =SUMIFS(Consolidado!$J:$J,Consolidado!$T:$T,Febrero!$B15,Consolidado!$L:$L,Febrero!U$21,Consolidado!$Q:$Q,Febrero!$B$11)+U28 -> 0 | V15: =SUMIFS(Consolidado!$J:$J,Consolidado!$T:$T,Febrero!$B15,Consolidado!$L:$L,Febrero!V$21,Consolidado!$Q:$Q,Febrero!$B$11)+V28 -> 0 | W15: =+SUM(C15:V15) -> 30824
B16: INFANTIL | C16: =SUMIFS(Consolidado!$J:$J,Consolidado!$T:$T,Febrero!$B16,Consolidado!$L:$L,Febrero!C$21,Consolidado!$Q:$Q,Febrero!$B$11)+SUM(C29:C32) -> 2643 | D16: =SUMIFS(Consolidado!$J:$J,Consolidado!$T:$T,Febrero!$B16,Consolidado!$L:$L,Febrero!D$21,Consolidado!$Q:$Q,Febrero!$B$11)+SUM(D29:D32) -> 927 | E16: =SUMIFS(Consolidado!$J:$J,Consolidado!$T:$T,Febrero!$B16,Consolidado!$L:$L,Febrero!E$21,Consolidado!$Q:$Q,Febrero!$B$11)+SUM(E29:E32) -> 900 | F16: =SUMIFS(Consolidado!$J:$J,Consolidado!$T:$T,Febrero!$B16,Consolidado!$L:$L,Febrero!F$21,Consolidado!$Q:$Q,Febrero!$B$11)+SUM(F29:F32) -> 7686 | G16: =SUMIFS(Consolidado!$J:$J,Consolidado!$T:$T,Febrero!$B16,Consolidado!$L:$L,Febrero!G$21,Consolidado!$Q:$Q,Febrero!$B$11)+SUM(G29:G32) -> 3880 | H16: =SUMIFS(Consolidado!$J:$J,Consolidado!$T:$T,Febrero!$B16,Consolidado!$L:$L,Febrero!H$21,Consolidado!$Q:$Q,Febrero!$B$11)+SUM(H29:H32) -> 3075 | I16: =SUMIFS(Consolidado!$J:$J,Consolidado!$T:$T,Febrero!$B16,Consolidado!$L:$L,Febrero!I$21,Consolidado!$Q:$Q,Febrero!$B$11)+SUM(I29:I32) -> 4192 | J16: =SUMIFS(Consolidado!$J:$J,Consolidado!$T:$T,Febrero!$B16,Consolidado!$L:$L,Febrero!J$21,Consolidado!$Q:$Q,Febrero!$B$11)+SUM(J29:J32) -> 1538 | ... S16: =SUMIFS(Consolidado!$J:$J,Consolidado!$T:$T,Febrero!$B16,Consolidado!$L:$L,Febrero!S$21,Consolidado!$Q:$Q,Febrero!$B$11)+SUM(S29:S32) -> 5303 | U16: =SUMIFS(Consolidado!$J:$J,Consolidado!$T:$T,Febrero!$B16,Consolidado!$L:$L,Febrero!U$21,Consolidado!$Q:$Q,Febrero!$B$11)+SUM(U29:U32) -> 0 | V16: =SUMIFS(Consolidado!$J:$J,Consolidado!$T:$T,Febrero!$B16,Consolidado!$L:$L,Febrero!V$21,Consolidado!$Q:$Q,Febrero!$B$11)+SUM(V29:V32) -> 0 | W16: =+SUM(C16:V16) -> 59651
B17: HOGAR Y COMPLEMENTOS | C17: =SUMIFS(Consolidado!$J:$J,Consolidado!$T:$T,Febrero!$B17,Consolidado!$L:$L,Febrero!C$21,Consolidado!$Q:$Q,Febrero!$B$11)+SUM(C33:C35) -> 2744 | D17: =SUMIFS(Consolidado!$J:$J,Consolidado!$T:$T,Febrero!$B17,Consolidado!$L:$L,Febrero!D$21,Consolidado!$Q:$Q,Febrero!$B$11)+SUM(D33:D35) -> 0 | E17: =SUMIFS(Consolidado!$J:$J,Consolidado!$T:$T,Febrero!$B17,Consolidado!$L:$L,Febrero!E$21,Consolidado!$Q:$Q,Febrero!$B$11)+SUM(E33:E35) -> 4800 | F17: =SUMIFS(Consolidado!$J:$J,Consolidado!$T:$T,Febrero!$B17,Consolidado!$L:$L,Febrero!F$21,Consolidado!$Q:$Q,Febrero!$B$11)+SUM(F33:F35) -> 0 | G17: =SUMIFS(Consolidado!$J:$J,Consolidado!$T:$T,Febrero!$B17,Consolidado!$L:$L,Febrero!G$21,Consolidado!$Q:$Q,Febrero!$B$11)+SUM(G33:G35) -> 1194 | H17: =SUMIFS(Consolidado!$J:$J,Consolidado!$T:$T,Febrero!$B17,Consolidado!$L:$L,Febrero!H$21,Consolidado!$Q:$Q,Febrero!$B$11)+SUM(H33:H35) -> 2340 | I17: =SUMIFS(Consolidado!$J:$J,Consolidado!$T:$T,Febrero!$B17,Consolidado!$L:$L,Febrero!I$21,Consolidado!$Q:$Q,Febrero!$B$11)+SUM(I33:I35) -> 276 | J17: =SUMIFS(Consolidado!$J:$J,Consolidado!$T:$T,Febrero!$B17,Consolidado!$L:$L,Febrero!J$21,Consolidado!$Q:$Q,Febrero!$B$11)+SUM(J33:J35) -> 4987 | ... S17: =SUMIFS(Consolidado!$J:$J,Consolidado!$T:$T,Febrero!$B17,Consolidado!$L:$L,Febrero!S$21,Consolidado!$Q:$Q,Febrero!$B$11)+SUM(S33:S35) -> 31868 | U17: =SUMIFS(Consolidado!$J:$J,Consolidado!$T:$T,Febrero!$B17,Consolidado!$L:$L,Febrero!U$21,Consolidado!$Q:$Q,Febrero!$B$11)+SUM(U33:U35) -> 0 | V17: =SUMIFS(Consolidado!$J:$J,Consolidado!$T:$T,Febrero!$B17,Consolidado!$L:$L,Febrero!V$21,Consolidado!$Q:$Q,Febrero!$B$11)+SUM(V33:V35) -> 0 | W17: =+SUM(C17:V17) -> 48209
B18: TOTAL | C18: =SUM(C13:C17) -> 26317 | D18: =SUM(D13:D17) -> 6306 | E18: =SUM(E13:E17) -> 16787 | F18: =SUM(F13:F17) -> 19381 | G18: =SUM(G13:G17) -> 17063 | H18: =SUM(H13:H17) -> 28706 | I18: =SUM(I13:I17) -> 26045 | J18: =SUM(J13:J17) -> 24307 | ... V18: =SUM(V13:V17) -> 0 | W18: =+SUM(C18:V18) -> 494468
B20: CEDI
B21: SUBCATEGORÍAS | C21: =+C12 -> 45323 | D21: =+D12 -> 45324 | E21: =+E12 -> 45327 | F21: =+F12 -> 45328 | G21: =+G12 -> 45329 | H21: =+H12 -> 45330 | I21: =+I12 -> 45331 | J21: =+J12 -> 45334 | ... S21: =+S12 -> 45345 | U21: =+U12 -> - | V21: =+V12 -> - | W21: TOTAL | X21: PPTO MES | Y21: DIF
B22: MUJER | C22: =SUMIFS(Consolidado!$J:$J,Consolidado!$B:$B,Febrero!$B22,Consolidado!$L:$L,Febrero!C$21,Consolidado!$Q:$Q,Febrero!$B$20) -> 1728 | D22: =SUMIFS(Consolidado!$J:$J,Consolidado!$B:$B,Febrero!$B22,Consolidado!$L:$L,Febrero!D$21,Consolidado!$Q:$Q,Febrero!$B$20) -> 5036 | E22: =SUMIFS(Consolidado!$J:$J,Consolidado!$B:$B,Febrero!$B22,Consolidado!$L:$L,Febrero!E$21,Consolidado!$Q:$Q,Febrero!$B$20) -> 5413 | F22: =SUMIFS(Consolidado!$J:$J,Consolidado!$B:$B,Febrero!$B22,Consolidado!$L:$L,Febrero!F$21,Consolidado!$Q:$Q,Febrero!$B$20) -> 344 | G22: =SUMIFS(Consolidado!$J:$J,Consolidado!$B:$B,Febrero!$B22,Consolidado!$L:$L,Febrero!G$21,Consolidado!$Q:$Q,Febrero!$B$20) -> 7894 | H22: =SUMIFS(Consolidado!$J:$J,Consolidado!$B:$B,Febrero!$B22,Consolidado!$L:$L,Febrero!H$21,Consolidado!$Q:$Q,Febrero!$B$20) -> 13627 | I22: =SUMIFS(Consolidado!$J:$J,Consolidado!$B:$B,Febrero!$B22,Consolidado!$L:$L,Febrero!I$21,Consolidado!$Q:$Q,Febrero!$B$20) -> 5746 | J22: =SUMIFS(Consolidado!$J:$J,Consolidado!$B:$B,Febrero!$B22,Consolidado!$L:$L,Febrero!J$21,Consolidado!$Q:$Q,Febrero!$B$20) -> 7962 | ... S22: =SUMIFS(Consolidado!$J:$J,Consolidado!$B:$B,Febrero!$B22,Consolidado!$L:$L,Febrero!S$21,Consolidado!$Q:$Q,Febrero!$B$20) -> 5296 | U22: =SUMIFS(Consolidado!$J:$J,Consolidado!$B:$B,Febrero!$B22,Consolidado!$L:$L,Febrero!U$21,Consolidado!$Q:$Q,Febrero!$B$20) -> 0 | V22: =SUMIFS(Consolidado!$J:$J,Consolidado!$B:$B,Febrero!$B22,Consolidado!$L:$L,Febrero!V$21,Consolidado!$Q:$Q,Febrero!$B$20) -> 0 | W22: =+SUM(C22:V22) -> 93335
B23: INT MUJER | C23: =SUMIFS(Consolidado!$J:$J,Consolidado!$B:$B,Febrero!$B23,Consolidado!$L:$L,Febrero!C$21,Consolidado!$Q:$Q,Febrero!$B$20) -> 1407 | D23: =SUMIFS(Consolidado!$J:$J,Consolidado!$B:$B,Febrero!$B23,Consolidado!$L:$L,Febrero!D$21,Consolidado!$Q:$Q,Febrero!$B$20) -> 0 | E23: =SUMIFS(Consolidado!$J:$J,Consolidado!$B:$B,Febrero!$B23,Consolidado!$L:$L,Febrero!E$21,Consolidado!$Q:$Q,Febrero!$B$20) -> 2380 | F23: =SUMIFS(Consolidado!$J:$J,Consolidado!$B:$B,Febrero!$B23,Consolidado!$L:$L,Febrero!F$21,Consolidado!$Q:$Q,Febrero!$B$20) -> 4632 | G23: =SUMIFS(Consolidado!$J:$J,Consolidado!$B:$B,Febrero!$B23,Consolidado!$L:$L,Febrero!G$21,Consolidado!$Q:$Q,Febrero!$B$20) -> 2445 | H23: =SUMIFS(Consolidado!$J:$J,Consolidado!$B:$B,Febrero!$B23,Consolidado!$L:$L,Febrero!H$21,Consolidado!$Q:$Q,Febrero!$B$20) -> 3232 | I23: =SUMIFS(Consolidado!$J:$J,Consolidado!$B:$B,Febrero!$B23,Consolidado!$L:$L,Febrero!I$21,Consolidado!$Q:$Q,Febrero!$B$20) -> 354 | J23: =SUMIFS(Consolidado!$J:$J,Consolidado!$B:$B,Febrero!$B23,Consolidado!$L:$L,Febrero!J$21,Consolidado!$Q:$Q,Febrero!$B$20) -> 1628 | ... S23: =SUMIFS(Consolidado!$J:$J,Consolidado!$B:$B,Febrero!$B23,Consolidado!$L:$L,Febrero!S$21,Consolidado!$Q:$Q,Febrero!$B$20) -> 14242 | U23: =SUMIFS(Consolidado!$J:$J,Consolidado!$B:$B,Febrero!$B23,Consolidado!$L:$L,Febrero!U$21,Consolidado!$Q:$Q,Febrero!$B$20) -> 0 | V23: =SUMIFS(Consolidado!$J:$J,Consolidado!$B:$B,Febrero!$B23,Consolidado!$L:$L,Febrero!V$21,Consolidado!$Q:$Q,Febrero!$B$20) -> 0 | W23: =+SUM(C23:V23) -> 70751
B24: INT HOMBRE | C24: =SUMIFS(Consolidado!$J:$J,Consolidado!$B:$B,Febrero!$B24,Consolidado!$L:$L,Febrero!C$21,Consolidado!$Q:$Q,Febrero!$B$20) -> 14997 | D24: =SUMIFS(Consolidado!$J:$J,Consolidado!$B:$B,Febrero!$B24,Consolidado!$L:$L,Febrero!D$21,Consolidado!$Q:$Q,Febrero!$B$20) -> 0 | E24: =SUMIFS(Consolidado!$J:$J,Consolidado!$B:$B,Febrero!$B24,Consolidado!$L:$L,Febrero!E$21,Consolidado!$Q:$Q,Febrero!$B$20) -> 0 | F24: =SUMIFS(Consolidado!$J:$J,Consolidado!$B:$B,Febrero!$B24,Consolidado!$L:$L,Febrero!F$21,Consolidado!$Q:$Q,Febrero!$B$20) -> 1910 | G24: =SUMIFS(Consolidado!$J:$J,Consolidado!$B:$B,Febrero!$B24,Consolidado!$L:$L,Febrero!G$21,Consolidado!$Q:$Q,Febrero!$B$20) -> 734 | H24: =SUMIFS(Consolidado!$J:$J,Consolidado!$B:$B,Febrero!$B24,Consolidado!$L:$L,Febrero!H$21,Consolidado!$Q:$Q,Febrero!$B$20) -> 0 | I24: =SUMIFS(Consolidado!$J:$J,Consolidado!$B:$B,Febrero!$B24,Consolidado!$L:$L,Febrero!I$21,Consolidado!$Q:$Q,Febrero!$B$20) -> 1204 | J24: =SUMIFS(Consolidado!$J:$J,Consolidado!$B:$B,Febrero!$B24,Consolidado!$L:$L,Febrero!J$21,Consolidado!$Q:$Q,Febrero!$B$20) -> 3915 | ... S24: =SUMIFS(Consolidado!$J:$J,Consolidado!$B:$B,Febrero!$B24,Consolidado!$L:$L,Febrero!S$21,Consolidado!$Q:$Q,Febrero!$B$20) -> 12685 | U24: =SUMIFS(Consolidado!$J:$J,Consolidado!$B:$B,Febrero!$B24,Consolidado!$L:$L,Febrero!U$21,Consolidado!$Q:$Q,Febrero!$B$20) -> 0 | V24: =SUMIFS(Consolidado!$J:$J,Consolidado!$B:$B,Febrero!$B24,Consolidado!$L:$L,Febrero!V$21,Consolidado!$Q:$Q,Febrero!$B$20) -> 0 | W24: =+SUM(C24:V24) -> 82850
